[2025-08-18T07:23:23.699+0000] {local_task_job_runner.py:120} INFO - ::group::Pre task execution logs
[2025-08-18T07:23:23.726+0000] {taskinstance.py:2076} INFO - Dependencies all met for dep_context=non-requeueable deps ti=<TaskInstance: dbt_pipeline.dbt_run manual__2025-08-18T07:23:23.356019+00:00 [queued]>
[2025-08-18T07:23:23.734+0000] {taskinstance.py:2076} INFO - Dependencies all met for dep_context=requeueable deps ti=<TaskInstance: dbt_pipeline.dbt_run manual__2025-08-18T07:23:23.356019+00:00 [queued]>
[2025-08-18T07:23:23.734+0000] {taskinstance.py:2306} INFO - Starting attempt 1 of 1
[2025-08-18T07:23:23.744+0000] {taskinstance.py:2330} INFO - Executing <Task(BashOperator): dbt_run> on 2025-08-18 07:23:23.356019+00:00
[2025-08-18T07:23:23.747+0000] {standard_task_runner.py:64} INFO - Started process 258 to run task
[2025-08-18T07:23:23.750+0000] {standard_task_runner.py:90} INFO - Running: ['airflow', 'tasks', 'run', 'dbt_pipeline', 'dbt_run', 'manual__2025-08-18T07:23:23.356019+00:00', '--job-id', '17', '--raw', '--subdir', 'DAGS_FOLDER/dbt_dag.py', '--cfg-path', '/tmp/tmpvx4qrw8i']
[2025-08-18T07:23:23.752+0000] {standard_task_runner.py:91} INFO - Job 17: Subtask dbt_run
[2025-08-18T07:23:23.790+0000] {task_command.py:426} INFO - Running <TaskInstance: dbt_pipeline.dbt_run manual__2025-08-18T07:23:23.356019+00:00 [running]> on host 9115d8d73e82
[2025-08-18T07:23:23.861+0000] {taskinstance.py:2648} INFO - Exporting env vars: AIRFLOW_CTX_DAG_OWNER='airflow' AIRFLOW_CTX_DAG_ID='dbt_pipeline' AIRFLOW_CTX_TASK_ID='dbt_run' AIRFLOW_CTX_EXECUTION_DATE='2025-08-18T07:23:23.356019+00:00' AIRFLOW_CTX_TRY_NUMBER='1' AIRFLOW_CTX_DAG_RUN_ID='manual__2025-08-18T07:23:23.356019+00:00'
[2025-08-18T07:23:23.861+0000] {taskinstance.py:430} INFO - ::endgroup::
[2025-08-18T07:23:23.874+0000] {subprocess.py:63} INFO - Tmp dir root location: /tmp
[2025-08-18T07:23:23.875+0000] {subprocess.py:75} INFO - Running command: ['/usr/bin/bash', '-c', 'cd /opt/airflow/my_dbt_project/my_dbt_project && dbt run']
[2025-08-18T07:23:23.881+0000] {subprocess.py:86} INFO - Output:
[2025-08-18T07:23:25.752+0000] {subprocess.py:93} INFO - [0m07:23:25  Running with dbt=1.10.9
[2025-08-18T07:23:26.051+0000] {subprocess.py:93} INFO - [0m07:23:26  Registered adapter: postgres=1.9.0
[2025-08-18T07:23:26.478+0000] {subprocess.py:93} INFO - [0m07:23:26  Found 4 models, 1 seed, 7 data tests, 1 source, 434 macros
[2025-08-18T07:23:26.481+0000] {subprocess.py:93} INFO - [0m07:23:26
[2025-08-18T07:23:26.481+0000] {subprocess.py:93} INFO - [0m07:23:26  Concurrency: 4 threads (target='dev')
[2025-08-18T07:23:26.482+0000] {subprocess.py:93} INFO - [0m07:23:26
[2025-08-18T07:23:26.537+0000] {subprocess.py:93} INFO - [0m07:23:26
[2025-08-18T07:23:26.537+0000] {subprocess.py:93} INFO - [0m07:23:26  Finished running  in 0 hours 0 minutes and 0.05 seconds (0.05s).
[2025-08-18T07:23:26.538+0000] {subprocess.py:93} INFO - [0m07:23:26  Encountered an error:
[2025-08-18T07:23:26.538+0000] {subprocess.py:93} INFO - Database Error
[2025-08-18T07:23:26.538+0000] {subprocess.py:93} INFO -   connection to server at "localhost" (::1), port 5432 failed: Connection refused
[2025-08-18T07:23:26.539+0000] {subprocess.py:93} INFO -   	Is the server running on that host and accepting TCP/IP connections?
[2025-08-18T07:23:26.539+0000] {subprocess.py:93} INFO -   connection to server at "localhost" (127.0.0.1), port 5432 failed: Connection refused
[2025-08-18T07:23:26.539+0000] {subprocess.py:93} INFO -   	Is the server running on that host and accepting TCP/IP connections?
[2025-08-18T07:23:26.539+0000] {subprocess.py:93} INFO - 
[2025-08-18T07:23:27.522+0000] {subprocess.py:97} INFO - Command exited with return code 2
[2025-08-18T07:23:27.523+0000] {taskinstance.py:441} INFO - ::group::Post task execution logs
[2025-08-18T07:23:27.537+0000] {taskinstance.py:2905} ERROR - Task failed with exception
Traceback (most recent call last):
  File "/home/airflow/.local/lib/python3.9/site-packages/airflow/models/taskinstance.py", line 465, in _execute_task
    result = _execute_callable(context=context, **execute_callable_kwargs)
  File "/home/airflow/.local/lib/python3.9/site-packages/airflow/models/taskinstance.py", line 432, in _execute_callable
    return execute_callable(context=context, **execute_callable_kwargs)
  File "/home/airflow/.local/lib/python3.9/site-packages/airflow/models/baseoperator.py", line 401, in wrapper
    return func(self, *args, **kwargs)
  File "/home/airflow/.local/lib/python3.9/site-packages/airflow/operators/bash.py", line 243, in execute
    raise AirflowException(
airflow.exceptions.AirflowException: Bash command failed. The command returned a non-zero exit code 2.
[2025-08-18T07:23:27.540+0000] {taskinstance.py:1206} INFO - Marking task as FAILED. dag_id=dbt_pipeline, task_id=dbt_run, run_id=manual__2025-08-18T07:23:23.356019+00:00, execution_date=20250818T072323, start_date=20250818T072323, end_date=20250818T072327
[2025-08-18T07:23:27.550+0000] {standard_task_runner.py:110} ERROR - Failed to execute job 17 for task dbt_run (Bash command failed. The command returned a non-zero exit code 2.; 258)
[2025-08-18T07:23:27.595+0000] {local_task_job_runner.py:243} INFO - Task exited with return code 1
[2025-08-18T07:23:27.617+0000] {taskinstance.py:3503} INFO - 0 downstream tasks scheduled from follow-on schedule check
[2025-08-18T07:23:27.620+0000] {local_task_job_runner.py:222} INFO - ::endgroup::
